No new conveyor detected, returning last connected conveyor

Connected to server (169.254.200.201) on port: 40001


Connected to server (169.254.200.200) on port: 40001

I get here 0
I get here 1
file path :  /home/au682915/Bachelor/Code/Python/saved_joints_poses.yaml
setup positions retrieved from saved_joints_poses.yaml file
I get here 2
Exception in thread Thread-3:
Traceback (most recent call last):
  File "/usr/lib/python3.10/threading.py", line 1016, in _bootstrap_inner
    self.run()
  File "/home/au682915/Bachelor/Code/Python/robots.py", line 54, in run
    self.robot_loop()
  File "/home/au682915/Bachelor/Code/Python/robots.py", line 84, in robot_loop
    check_order_failed(self.parent.cursor, int(data[0]))
  File "/home/au682915/Bachelor/Code/Python/DB_functions.py", line 128, in check_order_failed
    if(bool_value[0]):
TypeError: 'NoneType' object is not subscriptable
